<?xml version="1.0" ?>
<robot name="roslogh" xmlns:xacro="http://www.ros.org/wiki/xacro">

<xacro:include filename="$(find roslogh_description)/urdf/materials.xacro" />
<xacro:include filename="$(find roslogh_description)/urdf/roslogh.trans" />
<xacro:include filename="$(find roslogh_description)/urdf/roslogh.gazebo" />
<link name="base_link">
  <inertial>
    <origin xyz="0.02242999577947144 -6.8460879496483205e-09 0.004077074626700003" rpy="0 0 0"/>
    <mass value="1.7647631390827576"/>
    <inertia ixx="0.001798" iyy="0.007507" izz="0.008373" ixy="-0.0" iyz="1e-06" ixz="-0.000936"/>
  </inertial>
  <visual>
    <origin xyz="0 0 0" rpy="0 0 0"/>
    <geometry>
      <mesh filename="package://roslogh_description/meshes/base_link.stl" scale="0.001 0.001 0.001"/>
    </geometry>
    <material name="silver"/>
  </visual>
  <collision>
    <origin xyz="0 0 0" rpy="0 0 0"/>
    <geometry>
      <mesh filename="package://roslogh_description/meshes/base_link.stl" scale="0.001 0.001 0.001"/>
    </geometry>
  </collision>
</link>

<link name="left_1">
  <inertial>
    <origin xyz="0.0 0.0050000000000000044 -6.938893903907228e-18" rpy="0 0 0"/>
    <mass value="0.299177486388208"/>
    <inertia ixx="9.3e-05" iyy="0.000182" izz="9.3e-05" ixy="0.0" iyz="0.0" ixz="0.0"/>
  </inertial>
  <visual>
    <origin xyz="0.075 -0.06 0.025" rpy="0 0 0"/>
    <geometry>
      <mesh filename="package://roslogh_description/meshes/left_1.stl" scale="0.001 0.001 0.001"/>
    </geometry>
    <material name="silver"/>
  </visual>
  <collision>
    <origin xyz="0.075 -0.06 0.025" rpy="0 0 0"/>
    <geometry>
      <mesh filename="package://roslogh_description/meshes/left_1.stl" scale="0.001 0.001 0.001"/>
    </geometry>
  </collision>
</link>

<link name="right_1">
  <inertial>
    <origin xyz="-2.7755575615628914e-17 -0.0050000000000000044 0.0" rpy="0 0 0"/>
    <mass value="0.2991774863882081"/>
    <inertia ixx="9.3e-05" iyy="0.000182" izz="9.3e-05" ixy="0.0" iyz="0.0" ixz="-0.0"/>
  </inertial>
  <visual>
    <origin xyz="0.075 0.06 0.0225" rpy="0 0 0"/>
    <geometry>
      <mesh filename="package://roslogh_description/meshes/right_1.stl" scale="0.001 0.001 0.001"/>
    </geometry>
    <material name="silver"/>
  </visual>
  <collision>
    <origin xyz="0.075 0.06 0.0225" rpy="0 0 0"/>
    <geometry>
      <mesh filename="package://roslogh_description/meshes/right_1.stl" scale="0.001 0.001 0.001"/>
    </geometry>
  </collision>
</link>

<link name="lidar_1">
  <inertial>
    <origin xyz="-4.163336342344337e-17 0.0 0.009979528865946961" rpy="0 0 0"/>
    <mass value="0.249169834758972"/>
    <inertia ixx="4e-05" iyy="4e-05" izz="6.3e-05" ixy="-0.0" iyz="0.0" ixz="-0.0"/>
  </inertial>
  <visual>
    <origin xyz="-0.07 -0.0 -0.03" rpy="0 0 0"/>
    <geometry>
      <mesh filename="package://roslogh_description/meshes/lidar_1.stl" scale="0.001 0.001 0.001"/>
    </geometry>
    <material name="silver"/>
  </visual>
  <collision>
    <origin xyz="-0.07 -0.0 -0.03" rpy="0 0 0"/>
    <geometry>
      <mesh filename="package://roslogh_description/meshes/lidar_1.stl" scale="0.001 0.001 0.001"/>
    </geometry>
  </collision>
</link>

<joint name="Rev1" type="continuous">
  <origin xyz="-0.075 0.06 -0.025" rpy="0 0 0"/>
  <parent link="base_link"/>
  <child link="left_1"/>
  <axis xyz="0.0 1.0 0.0"/>
</joint>

<joint name="Rev2" type="continuous">
  <origin xyz="-0.075 -0.06 -0.0225" rpy="0 0 0"/>
  <parent link="base_link"/>
  <child link="right_1"/>
  <axis xyz="0.0 -1.0 0.0"/>
</joint>

<joint name="Rigid3" type="fixed">
  <origin xyz="0.07 0.0 0.03" rpy="0 0 0"/>
  <parent link="base_link"/>
  <child link="lidar_1"/>
</joint>

</robot>
